Workbook

Sheet EV_Data
A1: Model_Year | B1: Manufacturer | C1: Brand | D1: Model | E1: Drive_Type | F1: Vehicle_Class | G1: City_MPGe | H1: Hwy_MPGe | I1: Combined_MPGe | J1: Annual_Fuel_Cost | K1: FE_Rating | L1: GHG_Rating | M1: Savings_5yr | N1: Extra_Spend_5yr | O1: City_CO2 | P1: Hwy_CO2 | Q1: Combined_CO2 | R1: Range_Miles_Combined | S1: Range_Miles_City | T1: Range_Miles_Hwy | U1: Charge_Time_240V_hrs | V1: Charge_Time_120V_hrs | W1: Motor_Power_kW | X1: Battery_Type | Y1: Regen_Braking_Type
A2: 2025 | B2: Volkswagen Group of | C2: Audi | D2: Q8 e-tron quattro | E2: All Wheel Drive | F2: Standard SUV 4WD | G2: 44 | H2: 42 | I2: 43 | J2: 1050 | K2: 9 | L2: 10 | M2: 4250 | O2: 0 | P2: 0 | Q2: 0 | R2: 272 | S2: 267 | T2: 278 | U2: 16 | W2: 141 and 172 | X2: Lithium Ion | Y2: Electrical Regen Brake
A3: 2025 | B3: Volkswagen Group of | C3: Audi | D3: Q8 Sportback e-tron quattro | E3: All Wheel Drive | F3: Standard SUV 4WD | G3: 77 | H3: 80 | I3: 78 | J3: 1050 | K3: 9 | L3: 10 | M3: 4250 | O3: 0 | P3: 0 | Q3: 0 | R3: 272 | S3: 267 | T3: 278 | U3: 16 | W3: 141 and 172 | X3: Lithium Ion | Y3: Electrical Regen Brake
A4: 2025 | B4: Volkswagen Group of | C4: Audi | D4: Q8 Sportback e-tron quattro | E4: All Wheel Drive | F4: Standard SUV 4WD | G4: 44 | H4: 42 | I4: 43 | J4: 1050 | K4: 9 | L4: 10 | M4: 4250 | O4: 0 | P4: 0 | Q4: 0 | R4: 272 | S4: 267 | T4: 278 | U4: 16 | W4: 141 and 172 | X4: Lithium Ion | Y4: Electrical Regen Brake
A5: 2025 | B5: Volkswagen Group of | C5: Audi | D5: S e-tron GT (20in. Wheels) | E5: All Wheel Drive | F5: Subcompact Cars | G5: 91 | H5: 88 | I5: 90 | J5: 900 | K5: 9 | L5: 10 | M5: 5000 | O5: 0 | P5: 0 | Q5: 0 | R5: 300 | S5: 305 | T5: 294 | U5: 15.5 | W5: 176, 176 and 415 | X5: Lithium Ion | Y5: Electrical Regen Brake
A6: 2025 | B6: Volkswagen Group of | C6: Audi | D6: S e-tron GT (20in. Wheels) | E6: All Wheel Drive | F6: Subcompact Cars | G6: 37 | H6: 38 | I6: 38 | J6: 900 | K6: 9 | L6: 10 | M6: 5000 | O6: 0 | P6: 0 | Q6: 0 | R6: 300 | S6: 305 | T6: 294 | U6: 15.5 | W6: 176, 176 and 415 | X6: Lithium Ion | Y6: Electrical Regen Brake
A7: 2025 | B7: Volkswagen Group of | C7: Audi | D7: RS e-tron GT Performance | E7: All Wheel Drive | F7: Subcompact Cars | G7: 85 | H7: 82 | I7: 84 | J7: 950 | K7: 9 | L7: 10 | M7: 4750 | O7: 0 | P7: 0 | Q7: 0 | R7: 278 | S7: 283 | T7: 272 | U7: 15.5 | W7: 252 and 415 | X7: Lithium Ion | Y7: Electrical Regen Brake
A8: 2025 | B8: Volkswagen Group of | C8: Audi | D8: RS e-tron GT Performance | E8: All Wheel Drive | F8: Subcompact Cars | G8: 39 | H8: 41 | I8: 40 | J8: 950 | K8: 9 | L8: 10 | M8: 4750 | O8: 0 | P8: 0 | Q8: 0 | R8: 278 | S8: 283 | T8: 272 | U8: 15.5 | W8: 252 and 415 | X8: Lithium Ion | Y8: Electrical Regen Brake
A9: 2025 | B9: Volkswagen Group of | C9: Audi | D9: SQ8 e-tron (20in wheels) | E9: All Wheel Drive | F9: Standard SUV 4WD | G9: 68 | H9: 72 | I9: 70 | J9: 1150 | K9: 9 | L9: 10 | M9: 3750 | O9: 0 | P9: 0 | Q9: 0 | R9: 242 | S9: 237 | T9: 249 | U9: 16 | W9: 138 and 157 | X9: Lithium Ion | Y9: Electrical Regen Brake
A10: 2025 | B10: Volkswagen Group of | C10: Audi | D10: SQ8 e-tron (20in wheels) | E10: All Wheel Drive | F10: Standard SUV 4WD | G10: 49 | H10: 47 | I10: 48 | J10: 1150 | K10: 9 | L10: 10 | M10: 3750 | O10: 0 | P10: 0 | Q10: 0 | R10: 242 | S10: 237 | T10: 249 | U10: 16 | W10: 138 and 157 | X10: Lithium Ion | Y10: Electrical Regen Brake
A11: 2025 | B11: Volkswagen Group of | C11: Audi | D11: SQ8 Sportback e-tron (20in wheels) | E11: All Wheel Drive | F11: Standard SUV 4WD | G11: 68 | H11: 72 | I11: 70 | J11: 1150 | K11: 9 | L11: 10 | M11: 3750 | O11: 0 | P11: 0 | Q11: 0 | R11: 242 | S11: 237 | T11: 249 | U11: 16 | W11: 138 and 157 | X11: Lithium Ion | Y11: Electrical Regen Brake
A12: 2025 | B12: Volkswagen Group of | C12: Audi | D12: SQ8 Sportback e-tron (20in wheels) | E12: All Wheel Drive | F12: Standard SUV 4WD | G12: 49 | H12: 47 | I12: 48 | J12: 1150 | K12: 9 | L12: 10 | M12: 3750 | O12: 0 | P12: 0 | Q12: 0 | R12: 242 | S12: 237 | T12: 249 | U12: 16 | W12: 138 and 157 | X12: Lithium Ion | Y12: Electrical Regen Brake
A13: 2025 | B13: Volkswagen Group of | C13: Audi | D13: SQ8 e-tron (21/22in wheels) | E13: All Wheel Drive | F13: Standard SUV 4WD | G13: 59 | H13: 60 | I13: 60 | J13: 1350 | K13: 10 | L13: 10 | M13: 2750 | O13: 0 | P13: 0 | Q13: 0 | R13: 208 | S13: 206 | T13: 210 | U13: 16 | W13: 138 and 157 | X13: Lithium Ion | Y13: Electrical Regen Brake
... A666: 2025 | B666: Volvo | C666: Volvo Cars of North America, LLC | D666: EX30 Twin Performance (20 Inch Wheels) | E666: All Wheel Drive | F666: Small SUV 4WD | G666: 29 | H666: 34 | I666: 31 | J666: 750 | K666: 9 | L666: 10 | M666: 5750 | O666: 0 | P666: 0 | Q666: 0 | R666: 250 | S666: 269 | T666: 227 | U666: 8 | W666: 115 and 185 | X666: Lithium Ion | Y666: Electrical Regen Brake

Sheet EV_Pivot
A3: Row Labels | B3: Avg MPGe | C3: Avg Annual Fuel Cost | D3: Avg GHG Rating | E3: Avg Range(miles) | F3: Average of Savings_5yr
A4: Compact Cars | B4: 63.971429 | C4: 910 | D4: 10 | E4: 274.82857 | F4: 4942.8571
A5: Large Cars | B5: 67.960526 | C5: 812.5 | D5: 10 | E5: 357.31579 | F5: 5434.2105
A6: Midsize Cars | B6: 68.62 | C6: 808 | D6: 10 | E6: 280.2 | F6: 5460
A7: Midsize Station Wagons | B7: 61.5 | C7: 987.5 | D7: 10 | E7: 262.25 | F7: 4562.5
A8: Minicompact Cars | B8: 71.5 | C8: 725 | D8: 10 | E8: 145 | F8: 5875
A9: Small Station Wagons | B9: 61.5 | C9: 1000 | D9: 10 | E9: 303 | F9: 4500
A10: Small SUV 2WD | B10: 69.878788 | C10: 744.69697 | D10: 10 | E10: 268.36364 | F10: 5704.5455
A11: Small SUV 4WD | B11: 65.45 | C11: 860 | D11: 10 | E11: 257.72 | F11: 5200
A12: Special Purpose Vehicle 2WD | B12: 62.5 | C12: 950 | D12: 10 | E12: 176 | F12: 4750
A13: Special Purpose Vehicle 4WD | B13: 59.625 | C13: 1300 | D13: 10 | E13: 246.75 | F13: 3000
A14: Special Purpose Vehicle, minivan 2WD | B14: 62 | C14: 1000 | D14: 10 | E14: 234 | F14: 4500
A15: Special Purpose Vehicle, minivan 4WD | B15: 61 | C15: 1000 | D15: 10 | E15: 231 | F15: 4500
... A22: Grand Total | B22: 64.544361 | C22: 942.40602 | D22: 9.9879699 | E22: 294.88421 | F22: 4853.7594

Sheet ICE_Data
A1: Model_Year | B1: Manufacturer | C1: Brand | D1: Model | E1: Engine_Displacement | F1: Cylinders | G1: Transmission | H1: Num_Gears | I1: Drive_Type | J1: City_MPG | K1: Hwy_MPG | L1: Combined_MPG | M1: Vehicle_Class | N1: Annual_Fuel_Cost | O1: FE_Rating | P1: GHG_Rating | Q1: City_CO2 | R1: Hwy_CO2 | S1: Combined_CO2 | T1: Savings_5yr | U1: Extra_Spend_5yr | V1: Gas_Guzzler | W1: Air_Aspiration | X1: StopStart_System
A2: 2025 | B2: Honda | C2: Acura | D2: ADX AWD | E2: 1.5 | F2: 4 | G2: Auto(AV-S7) | H2: 7 | I2: All Wheel Drive | J2: 25 | K2: 30 | L2: 27 | M2: Small Station Wagons | N2: 2350 | O2: 5 | P2: 5 | Q2: 355 | R2: 291 | S2: 329 | U2: 2250 | W2: Turbocharged | X2: Yes
A3: 2025 | B3: Honda | C3: Acura | D3: ADX FWD | E3: 1.5 | F3: 4 | G3: Auto(AV-S7) | H3: 7 | I3: 2-Wheel Drive, Front | J3: 26 | K3: 31 | L3: 28 | M3: Small Station Wagons | N3: 2300 | O3: 6 | P3: 6 | Q3: 341 | R3: 286 | S3: 317 | U3: 2000 | W3: Turbocharged | X3: Yes
A4: 2025 | B4: Honda | C4: Acura | D4: INTEGRA | E4: 1.5 | F4: 4 | G4: Auto(AV-S7) | H4: 7 | I4: 2-Wheel Drive, Front | J4: 30 | K4: 37 | L4: 33 | M4: Large Cars | N4: 1950 | O4: 6 | P4: 6 | Q4: 296 | R4: 237 | S4: 269 | U4: 250 | W4: Turbocharged | X4: Yes
A5: 2025 | B5: Honda | C5: Acura | D5: INTEGRA | E5: 2 | F5: 4 | G5: Manual(M6) | H5: 6 | I5: 2-Wheel Drive, Front | J5: 21 | K5: 28 | L5: 24 | M5: Large Cars | N5: 2650 | O5: 5 | P5: 5 | Q5: 419 | R5: 312 | S5: 371 | U5: 3750 | W5: Turbocharged | X5: No
A6: 2025 | B6: Honda | C6: Acura | D6: INTEGRA A-SPEC | E6: 1.5 | F6: 4 | G6: Auto(AV-S7) | H6: 7 | I6: 2-Wheel Drive, Front | J6: 29 | K6: 36 | L6: 32 | M6: Large Cars | N6: 2000 | O6: 6 | P6: 6 | Q6: 304 | R6: 245 | S6: 277 | U6: 500 | W6: Turbocharged | X6: Yes
A7: 2025 | B7: Honda | C7: Acura | D7: INTEGRA A-SPEC | E7: 1.5 | F7: 4 | G7: Manual(M6) | H7: 6 | I7: 2-Wheel Drive, Front | J7: 26 | K7: 36 | L7: 30 | M7: Large Cars | N7: 2100 | O7: 6 | P7: 6 | Q7: 339 | R7: 241 | S7: 293 | U7: 1000 | W7: Turbocharged | X7: Yes
A8: 2025 | B8: Honda | C8: Acura | D8: MDX AWD | E8: 3.5 | F8: 6 | G8: Auto(S10) | H8: 10 | I8: All Wheel Drive | J8: 19 | K8: 25 | L8: 21 | M8: Small SUV 4WD | N8: 3050 | O8: 4 | P8: 4 | Q8: 477 | R8: 357 | S8: 423 | U8: 5750 | W8: Naturally Aspirated | X8: Yes
A9: 2025 | B9: Honda | C9: Acura | D9: MDX AWD Type-S | E9: 3 | F9: 6 | G9: Auto(S10) | H9: 10 | I9: All Wheel Drive | J9: 17 | K9: 21 | L9: 19 | M9: Standard SUV 4WD | N9: 3350 | O9: 4 | P9: 4 | Q9: 523 | R9: 414 | S9: 474 | U9: 7250 | W9: Turbocharged | X9: Yes
A10: 2025 | B10: Honda | C10: Acura | D10: MDX FWD | E10: 3.5 | F10: 6 | G10: Auto(S10) | H10: 10 | I10: 2-Wheel Drive, Front | J10: 19 | K10: 26 | L10: 22 | M10: Small SUV 2WD | N10: 2900 | O10: 5 | P10: 5 | Q10: 470 | R10: 339 | S10: 411 | U10: 5000 | W10: Naturally Aspirated | X10: Yes
A11: 2025 | B11: Honda | C11: Acura | D11: RDX AWD | E11: 2 | F11: 4 | G11: Auto(S10) | H11: 10 | I11: All Wheel Drive | J11: 21 | K11: 27 | L11: 23 | M11: Small SUV 4WD | N11: 2750 | O11: 5 | P11: 5 | Q11: 415 | R11: 322 | S11: 385 | U11: 4250 | W11: Turbocharged | X11: Yes
A12: 2025 | B12: Honda | C12: Acura | D12: RDX AWD A-SPEC | E12: 2 | F12: 4 | G12: Auto(S10) | H12: 10 | I12: All Wheel Drive | J12: 21 | K12: 26 | L12: 23 | M12: Small SUV 4WD | N12: 2750 | O12: 5 | P12: 5 | Q12: 423 | R12: 342 | S12: 386 | U12: 4250 | W12: Turbocharged | X12: Yes
A13: 2025 | B13: Honda | C13: Acura | D13: TLX AWD A-SPEC | E13: 2 | F13: 4 | G13: Auto(S10) | H13: 10 | I13: All Wheel Drive | J13: 21 | K13: 29 | L13: 24 | M13: Compact Cars | N13: 2650 | O13: 5 | P13: 5 | Q13: 425 | R13: 305 | S13: 371 | U13: 3750 | W13: Turbocharged | X13: Yes
... A21: 2025 | B21: aston martin | C21: Aston Martin Lagonda Ltd | D21: DBX 707 | E21: 4 | F21: 8 | G21: Auto(A9) | H21: 9 | I21: 4-Wheel Drive | J21: 15 | K21: 20 | L21: 17 | M21: Standard SUV 4WD | N21: 3750 | O21: 3 | P21: 3 | Q21: 602 | R21: 457 | S21: 536 | U21: 9250 | W21: Turbocharged | X21: No
A22: 2025 | B22: aston martin | C22: Aston Martin Lagonda Ltd | D22: Vanquish | E22: 5.2 | F22: 12 | G22: Auto(A8) | H22: 8 | I22: 2-Wheel Drive, Rear | J22: 13 | K22: 21 | L22: 16 | M22: Two Seaters | N22: 4000 | O22: 3 | P22: 3 | Q22: 671 | R22: 431 | S22: 563 | U22: 10500 | V22: G | W22: Turbocharged | X22: No
A23: 2025 | B23: aston martin | C23: Aston Martin Lagonda Ltd | D23: Vantage | E23: 4 | F23: 8 | G23: Auto(A8) | H23: 8 | I23: 2-Wheel Drive, Rear | J23: 15 | K23: 22 | L23: 18 | M23: Two Seaters | N23: 3550 | O23: 4 | P23: 4 | Q23: 579 | R23: 399 | S23: 498 | U23: 8250 | W23: Turbocharged | X23: No
A24: 2025 | B24: Volkswagen Group of | C24: Audi | D24: A3 quattro | E24: 2 | F24: 4 | G24: Auto(AM-S7) | H24: 7 | I24: All Wheel Drive | J24: 24 | K24: 34 | L24: 28 | M24: Subcompact Cars | N24: 2300 | O24: 6 | P24: 6 | Q24: 364 | R24: 262 | S24: 318 | U24: 2000 | W24: Turbocharged | X24: Yes
A25: 2025 | B25: Volkswagen Group of | C25: Audi | D25: A4 allroad quattro | E25: 2 | F25: 4 | G25: Auto(AM-S7) | H25: 7 | I25: All Wheel Drive | J25: 23 | K25: 30 | L25: 26 | M25: Small Station Wagons | N25: 2450 | O25: 5 | P25: 5 | Q25: 389 | R25: 293 | S25: 346 | U25: 2750 | W25: Turbocharged | X25: Yes
A26: 2025 | B26: Volkswagen Group of | C26: Audi | D26: A4 quattro | E26: 2 | F26: 4 | G26: Auto(AM-S7) | H26: 7 | I26: All Wheel Drive | J26: 26 | K26: 36 | L26: 29 | M26: Compact Cars | N26: 2200 | O26: 6 | P26: 6 | Q26: 344 | R26: 248 | S26: 301 | U26: 1500 | W26: Turbocharged | X26: Yes
A27: 2025 | B27: Volkswagen Group of | C27: Audi | D27: A4 S line quattro | E27: 2 | F27: 4 | G27: Auto(AM-S7) | H27: 7 | I27: All Wheel Drive | J27: 23 | K27: 32 | L27: 26 | M27: Compact Cars | N27: 2450 | O27: 5 | P27: 5 | Q27: 389 | R27: 279 | S27: 339 | U27: 2750 | W27: Turbocharged | X27: Yes
A28: 2025 | B28: Volkswagen Group of | C28: Audi | D28: A5 quattro | E28: 2 | F28: 4 | G28: Auto(AM-S7) | H28: 7 | I28: All Wheel Drive | J28: 22 | K28: 31 | L28: 26 | M28: Midsize Cars | N28: 2450 | O28: 5 | P28: 5 | Q28: 399 | R28: 287 | S28: 349 | U28: 2750 | W28: Turbocharged | X28: Yes
A29: 2025 | B29: Volkswagen Group of | C29: Audi | D29: A5 Sportback quattro | E29: 2 | F29: 4 | G29: Auto(AM-S7) | H29: 7 | I29: All Wheel Drive | J29: 26 | K29: 36 | L29: 29 | M29: Midsize Cars | N29: 2200 | O29: 6 | P29: 6 | Q29: 344 | R29: 248 | S29: 301 | U29: 1500 | W29: Turbocharged | X29: Yes
A30: 2025 | B30: Volkswagen Group of | C30: Audi | D30: A5 Sportback S line quattro | E30: 2 | F30: 4 | G30: Auto(AM-S7) | H30: 7 | I30: All Wheel Drive | J30: 23 | K30: 32 | L30: 26 | M30: Midsize Cars | N30: 2450 | O30: 5 | P30: 5 | Q30: 389 | R30: 279 | S30: 339 | U30: 2750 | W30: Turbocharged | X30: Yes
A31: 2025 | B31: Volkswagen Group of | C31: Audi | D31: A6 allroad quattro | E31: 3 | F31: 6 | G31: Auto(AM-S7) | H31: 7 | I31: All Wheel Drive | J31: 22 | K31: 30 | L31: 25 | M31: Midsize Station Wagons | N31: 2550 | O31: 5 | P31: 5 | Q31: 406 | R31: 295 | S31: 356 | U31: 3250 | W31: Turbocharged | X31: Yes
A32: 2025 | B32: Volkswagen Group of | C32: Audi | D32: A6 quattro | E32: 2 | F32: 4 | G32: Auto(AM-S7) | H32: 7 | I32: All Wheel Drive | J32: 24 | K32: 31 | L32: 26 | M32: Midsize Cars | N32: 2450 | O32: 5 | P32: 5 | Q32: 379 | R32: 291 | S32: 339 | U32: 2750 | W32: Turbocharged | X32: Yes
A33: 2025 | B33: Volkswagen Group of | C33: Audi | D33: A6 quattro | E33: 3 | F33: 6 | G33: Auto(AM-S7) | H33: 7 | I33: All Wheel Drive | J33: 22 | K33: 30 | L33: 25 | M33: Midsize Cars | N33: 2550 | O33: 5 | P33: 5 | Q33: 406 | R33: 295 | S33: 356 | U33: 3250 | W33: Turbocharged | X33: Yes
A34: 2025 | B34: Volkswagen Group of | C34: Audi | D34: A7 quattro | E34: 3 | F34: 6 | G34: Auto(AM-S7) | H34: 7 | I34: All Wheel Drive | J34: 22 | K34: 30 | L34: 25 | M34: Midsize Cars | N34: 2550 | O34: 5 | P34: 5 | Q34: 406 | R34: 295 | S34: 356 | U34: 3250 | W34: Turbocharged | X34: Yes
... A47: 2025 | B47: Volkswagen Group of | C47: Audi | D47: RS 5 Sportback | E47: 2.9 | F47: 6 | G47: Auto(S8) | H47: 8 | I47: All Wheel Drive | J47: 18 | K47: 25 | L47: 20 | M47: Midsize Cars | N47: 3200 | O47: 4 | P47: 4 | Q47: 502 | R47: 361 | S47: 438 | U47: 6500 | W47: Turbocharged | X47: No
A48: 2025 | B48: Volkswagen Group of | C48: Audi | D48: RS 6 Avant | E48: 4 | F48: 8 | G48: Auto(S8) | H48: 8 | I48: All Wheel Drive | J48: 14 | K48: 21 | L48: 17 | M48: Midsize Station Wagons | N48: 3750 | O48: 3 | P48: 3 | Q48: 638 | R48: 416 | S48: 538 | U48: 9250 | V48: G | W48: Turbocharged | X48: Yes
A49: 2025 | B49: Volkswagen Group of | C49: Audi | D49: RS 7 | E49: 4 | F49: 8 | G49: Auto(S8) | H49: 8 | I49: All Wheel Drive | J49: 14 | K49: 21 | L49: 17 | M49: Midsize Cars | N49: 3750 | O49: 3 | P49: 3 | Q49: 638 | R49: 416 | S49: 538 | U49: 9250 | V49: G | W49: Turbocharged | X49: Yes
A50: 2025 | B50: Volkswagen Group of | C50: Audi | D50: RS Q8 Performance | E50: 4 | F50: 8 | G50: Auto(S8) | H50: 8 | I50: All Wheel Drive | J50: 14 | K50: 20 | L50: 16 | M50: Standard SUV 4WD | N50: 4000 | O50: 3 | P50: 3 | Q50: 622 | R50: 454 | S50: 547 | U50: 10500 | W50: Turbocharged | X50: Yes
A51: 2025 | B51: Volkswagen Group of | C51: Audi | D51: S3 | E51: 2 | F51: 4 | G51: Auto(AM-S7) | H51: 7 | I51: All Wheel Drive | J51: 23 | K51: 31 | L51: 26 | M51: Subcompact Cars | N51: 2450 | O51: 5 | P51: 5 | Q51: 392 | R51: 285 | S51: 344 | U51: 2750 | W51: Turbocharged | X51: Yes
A52: 2025 | B52: Volkswagen Group of | C52: Audi | D52: S4 | E52: 3 | F52: 6 | G52: Auto(S8) | H52: 8 | I52: All Wheel Drive | J52: 20 | K52: 29 | L52: 24 | M52: Compact Cars | N52: 2650 | O52: 5 | P52: 5 | Q52: 433 | R52: 308 | S52: 377 | U52: 3750 | W52: Turbocharged | X52: Yes
A53: 2025 | B53: Volkswagen Group of | C53: Audi | D53: S5 | E53: 3 | F53: 6 | G53: Auto(AM-S7) | H53: 7 | I53: All Wheel Drive | J53: 19 | K53: 28 | L53: 22 | M53: Midsize Cars | N53: 2900 | O53: 5 | P53: 5 | Q53: 466 | R53: 314 | S53: 397 | U53: 5000 | W53: Turbocharged | X53: Yes
A54: 2025 | B54: Volkswagen Group of | C54: Audi | D54: S5 Sportback | E54: 3 | F54: 6 | G54: Auto(S8) | H54: 8 | I54: All Wheel Drive | J54: 20 | K54: 29 | L54: 23 | M54: Midsize Cars | N54: 2750 | O54: 5 | P54: 5 | Q54: 444 | R54: 311 | S54: 384 | U54: 4250 | W54: Turbocharged | X54: Yes
A55: 2025 | B55: Volkswagen Group of | C55: Audi | D55: S6 | E55: 2.9 | F55: 6 | G55: Auto(S8) | H55: 8 | I55: All Wheel Drive | J55: 19 | K55: 27 | L55: 22 | M55: Midsize Cars | N55: 2900 | O55: 5 | P55: 5 | Q55: 468 | R55: 335 | S55: 408 | U55: 5000 | W55: Other | X55: Yes
A56: 2025 | B56: Volkswagen Group of | C56: Audi | D56: S7 | E56: 2.9 | F56: 6 | G56: Auto(S8) | H56: 8 | I56: All Wheel Drive | J56: 19 | K56: 27 | L56: 22 | M56: Midsize Cars | N56: 2900 | O56: 5 | P56: 5 | Q56: 468 | R56: 335 | S56: 408 | U56: 5000 | W56: Other | X56: Yes
A57: 2025 | B57: Volkswagen Group of | C57: Audi | D57: S8 | E57: 4 | F57: 8 | G57: Auto(S8) | H57: 8 | I57: All Wheel Drive | J57: 15 | K57: 24 | L57: 18 | M57: Large Cars | N57: 3550 | O57: 4 | P57: 4 | Q57: 605 | R57: 377 | S57: 502 | U57: 8250 | W57: Turbocharged | X57: Yes
A58: 2025 | B58: Volkswagen Group of | C58: Audi | D58: SQ5 | E58: 3 | F58: 6 | G58: Auto(S8) | H58: 8 | I58: All Wheel Drive | J58: 19 | K58: 24 | L58: 21 | M58: Small SUV 4WD | N58: 3050 | O58: 4 | P58: 4 | Q58: 474 | R58: 370 | S58: 427 | U58: 5750 | W58: Turbocharged | X58: Yes
A59: 2025 | B59: Volkswagen Group of | C59: Audi | D59: SQ5 | E59: 3 | F59: 6 | G59: Auto(AM-S7) | H59: 7 | I59: All Wheel Drive | J59: 19 | K59: 26 | L59: 22 | M59: Small SUV 4WD | N59: 2900 | O59: 5 | P59: 5 | Q59: 460 | R59: 336 | S59: 404 | U59: 5000 | W59: Turbocharged | X59: Yes
...

Sheet ICE_Pivot
A3: Row Labels | B3: Avg MPG | C3: Avg Annual Fuel Cost | D3: Avg GHG Rating | E3: Average of Extra_Spend_5yr
A4: Compact Cars | B4: 28.708333 | C4: 2249.3056 | D4: 5.6111111 | E4: 3490
A5: Large Cars | B5: 25.358974 | C5: 2688.4615 | D5: 4.8205128 | E5: 5922.4138
A6: Midsize Cars | B6: 30.277108 | C6: 2160.241 | D6: 5.6746988 | E6: 4122.3404
A7: Midsize Station Wagons | B7: 23 | C7: 2830 | D7: 4.6 | E7: 4650
A8: Minicompact Cars | B8: 20.413793 | C8: 3227.5862 | D8: 4.137931 | E8: 6637.931
A9: Small Pick-up Trucks 2WD | B9: 26.5 | C9: 2100 | D9: 5.5 | E9: 2166.6667
A10: Small Pick-up Trucks 4WD | B10: 23.666667 | C10: 2288.8889 | D10: 4.6666667 | E10: 2500
A11: Small Station Wagons | B11: 27.421053 | C11: 2171.0526 | D11: 5.4210526 | E11: 3777.7778
A12: Small SUV 2WD | B12: 28.315789 | C12: 1985.0877 | D12: 5.5964912 | E12: 2043.1034
A13: Small SUV 4WD | B13: 25.3 | C13: 2335.8824 | D13: 5.0705882 | E13: 3173.6641
A14: Special Purpose Vehicle 2WD | B14: 28.5 | C14: 2250 | D14: 6 | E14: 1750
A15: Special Purpose Vehicle cab chassis | B15: 15.5 | C15: 3400 | D15: 2.5 | E15: 7500
... A24: Grand Total | B24: 23.892857 | C24: 2641.6475 | D24: 4.6912442 | E24: 4873.5994

Sheet Comparison
A1: Vehicle_Class | B1: Avg EV MPGe | C1: Avg ICE MPG | D1: Avg EV Fuel Cost | E1: Avg ICE Fuel Cost | F1: Fuel Cost Difference | G1: Avg EV GHG | H1: Avg ICE GHG
A2: Compact Cars | B2: =VLOOKUP(A2,EV_Pivot!$A$4:$E$21,2,0) -> 63.971429 | C2: =VLOOKUP(A2,ICE_Pivot!$A$4:$E$23,2,0) -> 28.708333 | D2: =VLOOKUP(A2,EV_Pivot!$A$4:$E$21,3,0) -> 910 | E2: =VLOOKUP(A2,ICE_Pivot!$A$4:$E$23,3,0) -> 2249.3056 | F2: =(E2-D2) -> 1339.3056 | G2: =VLOOKUP(A2,EV_Pivot!$A$4:$E$21,4,0) -> 10 | H2: =VLOOKUP(A2,ICE_Pivot!$A$4:$E$23,4,0) -> 5.6111111
A3: Large Cars | B3: =VLOOKUP(A3,EV_Pivot!$A$4:$E$21,2,0) -> 67.960526 | C3: =VLOOKUP(A3,ICE_Pivot!$A$4:$E$23,2,0) -> 25.358974 | D3: =VLOOKUP(A3,EV_Pivot!$A$4:$E$21,3,0) -> 812.5 | E3: =VLOOKUP(A3,ICE_Pivot!$A$4:$E$23,3,0) -> 2688.4615 | F3: =(E3-D3) -> 1875.9615 | G3: =VLOOKUP(A3,EV_Pivot!$A$4:$E$21,4,0) -> 10 | H3: =VLOOKUP(A3,ICE_Pivot!$A$4:$E$23,4,0) -> 4.8205128
A4: Midsize Cars | B4: =VLOOKUP(A4,EV_Pivot!$A$4:$E$21,2,0) -> 68.62 | C4: =VLOOKUP(A4,ICE_Pivot!$A$4:$E$23,2,0) -> 30.277108 | D4: =VLOOKUP(A4,EV_Pivot!$A$4:$E$21,3,0) -> 808 | E4: =VLOOKUP(A4,ICE_Pivot!$A$4:$E$23,3,0) -> 2160.241 | F4: =(E4-D4) -> 1352.241 | G4: =VLOOKUP(A4,EV_Pivot!$A$4:$E$21,4,0) -> 10 | H4: =VLOOKUP(A4,ICE_Pivot!$A$4:$E$23,4,0) -> 5.6746988
A5: Midsize Station Wagons | B5: =VLOOKUP(A5,EV_Pivot!$A$4:$E$21,2,0) -> 61.5 | C5: =VLOOKUP(A5,ICE_Pivot!$A$4:$E$23,2,0) -> 23 | D5: =VLOOKUP(A5,EV_Pivot!$A$4:$E$21,3,0) -> 987.5 | E5: =VLOOKUP(A5,ICE_Pivot!$A$4:$E$23,3,0) -> 2830 | F5: =(E5-D5) -> 1842.5 | G5: =VLOOKUP(A5,EV_Pivot!$A$4:$E$21,4,0) -> 10 | H5: =VLOOKUP(A5,ICE_Pivot!$A$4:$E$23,4,0) -> 4.6
A6: Minicompact Cars | B6: =VLOOKUP(A6,EV_Pivot!$A$4:$E$21,2,0) -> 71.5 | C6: =VLOOKUP(A6,ICE_Pivot!$A$4:$E$23,2,0) -> 20.413793 | D6: =VLOOKUP(A6,EV_Pivot!$A$4:$E$21,3,0) -> 725 | E6: =VLOOKUP(A6,ICE_Pivot!$A$4:$E$23,3,0) -> 3227.5862 | F6: =(E6-D6) -> 2502.5862 | G6: =VLOOKUP(A6,EV_Pivot!$A$4:$E$21,4,0) -> 10 | H6: =VLOOKUP(A6,ICE_Pivot!$A$4:$E$23,4,0) -> 4.137931
A7: Small Pick-up Trucks 2WD | B7: N/A | C7: =VLOOKUP(A7,ICE_Pivot!$A$4:$E$23,2,0) -> 26.5 | D7: N/A | E7: =VLOOKUP(A7,ICE_Pivot!$A$4:$E$23,3,0) -> 2100 | F7: =IF(D7="N/A","N/A",E7-D7) -> N/A | G7: =IF(D7="N/A","N/A",E7-D7) -> N/A | H7: =VLOOKUP(A7,ICE_Pivot!$A$4:$E$23,4,0) -> 5.5
A8: Small Pick-up Trucks 4WD | B8: N/A | C8: =VLOOKUP(A8,ICE_Pivot!$A$4:$E$23,2,0) -> 23.666667 | D8: N/A | E8: =VLOOKUP(A8,ICE_Pivot!$A$4:$E$23,3,0) -> 2288.8889 | F8: =IF(D8="N/A","N/A",E8-D8) -> N/A | G8: =IF(D8="N/A","N/A",E8-D8) -> N/A | H8: =VLOOKUP(A8,ICE_Pivot!$A$4:$E$23,4,0) -> 4.6666667
A9: Small Station Wagons | B9: =VLOOKUP(A9,EV_Pivot!$A$4:$E$21,2,0) -> 61.5 | C9: =VLOOKUP(A9,ICE_Pivot!$A$4:$E$23,2,0) -> 27.421053 | D9: =VLOOKUP(A9,EV_Pivot!$A$4:$E$21,3,0) -> 1000 | E9: =VLOOKUP(A9,ICE_Pivot!$A$4:$E$23,3,0) -> 2171.0526 | F9: =(E9-D9) -> 1171.0526 | G9: =VLOOKUP(A9,EV_Pivot!$A$4:$E$21,4,0) -> 10 | H9: =VLOOKUP(A9,ICE_Pivot!$A$4:$E$23,4,0) -> 5.4210526
A10: Small SUV 2WD | B10: =VLOOKUP(A10,EV_Pivot!$A$4:$E$21,2,0) -> 69.878788 | C10: =VLOOKUP(A10,ICE_Pivot!$A$4:$E$23,2,0) -> 28.315789 | D10: =VLOOKUP(A10,EV_Pivot!$A$4:$E$21,3,0) -> 744.69697 | E10: =VLOOKUP(A10,ICE_Pivot!$A$4:$E$23,3,0) -> 1985.0877 | F10: =(E10-D10) -> 1240.3907 | G10: =VLOOKUP(A10,EV_Pivot!$A$4:$E$21,4,0) -> 10 | H10: =VLOOKUP(A10,ICE_Pivot!$A$4:$E$23,4,0) -> 5.5964912
A11: Small SUV 4WD | B11: =VLOOKUP(A11,EV_Pivot!$A$4:$E$21,2,0) -> 65.45 | C11: =VLOOKUP(A11,ICE_Pivot!$A$4:$E$23,2,0) -> 25.3 | D11: =VLOOKUP(A11,EV_Pivot!$A$4:$E$21,3,0) -> 860 | E11: =VLOOKUP(A11,ICE_Pivot!$A$4:$E$23,3,0) -> 2335.8824 | F11: =(E11-D11) -> 1475.8824 | G11: =VLOOKUP(A11,EV_Pivot!$A$4:$E$21,4,0) -> 10 | H11: =VLOOKUP(A11,ICE_Pivot!$A$4:$E$23,4,0) -> 5.0705882
A12: Special Purpose Vehicle 2WD | B12: =VLOOKUP(A12,EV_Pivot!$A$4:$E$21,2,0) -> 62.5 | C12: =VLOOKUP(A12,ICE_Pivot!$A$4:$E$23,2,0) -> 28.5 | D12: =VLOOKUP(A12,EV_Pivot!$A$4:$E$21,3,0) -> 950 | E12: =VLOOKUP(A12,ICE_Pivot!$A$4:$E$23,3,0) -> 2250 | F12: =(E12-D12) -> 1300 | G12: =VLOOKUP(A12,EV_Pivot!$A$4:$E$21,4,0) -> 10 | H12: =VLOOKUP(A12,ICE_Pivot!$A$4:$E$23,4,0) -> 6
A13: Special Purpose Vehicle cab chassis | B13: N/A | C13: =VLOOKUP(A13,ICE_Pivot!$A$4:$E$23,2,0) -> 15.5 | D13: N/A | E13: =VLOOKUP(A13,ICE_Pivot!$A$4:$E$23,3,0) -> 3400 | F13: N/A | G13: N/A | H13: =VLOOKUP(A13,ICE_Pivot!$A$4:$E$23,4,0) -> 2.5
A14: Special Purpose Vehicle, minivan 2WD | B14: =VLOOKUP(A14,EV_Pivot!$A$4:$E$21,2,0) -> 62 | C14: =VLOOKUP(A14,ICE_Pivot!$A$4:$E$23,2,0) -> 26 | D14: =VLOOKUP(A14,EV_Pivot!$A$4:$E$21,3,0) -> 1000 | E14: =VLOOKUP(A14,ICE_Pivot!$A$4:$E$23,3,0) -> 2125 | F14: =(E14-D14) -> 1125 | G14: =VLOOKUP(A14,EV_Pivot!$A$4:$E$21,4,0) -> 10 | H14: =VLOOKUP(A14,ICE_Pivot!$A$4:$E$23,4,0) -> 5.3333333
A15: Special Purpose Vehicle, minivan 4WD | B15: =VLOOKUP(A15,EV_Pivot!$A$4:$E$21,2,0) -> 61 | C15: =VLOOKUP(A15,ICE_Pivot!$A$4:$E$23,2,0) -> 27.5 | D15: =VLOOKUP(A15,EV_Pivot!$A$4:$E$21,3,0) -> 1000 | E15: =VLOOKUP(A15,ICE_Pivot!$A$4:$E$23,3,0) -> 2050 | F15: =(E15-D15) -> 1050 | G15: =VLOOKUP(A15,EV_Pivot!$A$4:$E$21,4,0) -> 10 | H15: =VLOOKUP(A15,ICE_Pivot!$A$4:$E$23,4,0) -> 5.5
A16: Standard Pick-up Trucks 2WD | B16: =VLOOKUP(A16,EV_Pivot!$A$4:$E$21,2,0) -> 61 | C16: =VLOOKUP(A16,ICE_Pivot!$A$4:$E$23,2,0) -> 20.478261 | D16: =VLOOKUP(A16,EV_Pivot!$A$4:$E$21,3,0) -> 1025 | E16: =VLOOKUP(A16,ICE_Pivot!$A$4:$E$23,3,0) -> 2615.2174 | F16: =(E16-D16) -> 1590.2174 | G16: =VLOOKUP(A16,EV_Pivot!$A$4:$E$21,4,0) -> 10 | H16: =VLOOKUP(A16,ICE_Pivot!$A$4:$E$23,4,0) -> 4.2173913
A17: Standard Pick-up Trucks 4WD | B17: =VLOOKUP(A17,EV_Pivot!$A$4:$E$21,2,0) -> 60.064103 | C17: =VLOOKUP(A17,ICE_Pivot!$A$4:$E$23,2,0) -> 18.171429 | D17: =VLOOKUP(A17,EV_Pivot!$A$4:$E$21,3,0) -> 1269.2308 | E17: =VLOOKUP(A17,ICE_Pivot!$A$4:$E$23,3,0) -> 3088.5714 | F17: =(E17-D17) -> 1819.3407 | G17: =VLOOKUP(A17,EV_Pivot!$A$4:$E$21,4,0) -> 9.8974359 | H17: =VLOOKUP(A17,ICE_Pivot!$A$4:$E$23,4,0) -> 3.4285714
A18: Standard SUV 2WD | B18: =VLOOKUP(A18,EV_Pivot!$A$4:$E$21,2,0) -> 65.541667 | C18: =VLOOKUP(A18,ICE_Pivot!$A$4:$E$23,2,0) -> 20.973684 | D18: =VLOOKUP(A18,EV_Pivot!$A$4:$E$21,3,0) -> 852.08333 | E18: =VLOOKUP(A18,ICE_Pivot!$A$4:$E$23,3,0) -> 2785.5263 | F18: =(E18-D18) -> 1933.443 | G18: =VLOOKUP(A18,EV_Pivot!$A$4:$E$21,4,0) -> 10 | H18: =VLOOKUP(A18,ICE_Pivot!$A$4:$E$23,4,0) -> 4.1578947
A19: Standard SUV 4WD | B19: =VLOOKUP(A19,EV_Pivot!$A$4:$E$21,2,0) -> 61.819355 | C19: =VLOOKUP(A19,ICE_Pivot!$A$4:$E$23,2,0) -> 19.5 | D19: =VLOOKUP(A19,EV_Pivot!$A$4:$E$21,3,0) -> 1015.8065 | E19: =VLOOKUP(A19,ICE_Pivot!$A$4:$E$23,3,0) -> 3213.4328 | F19: =(E19-D19) -> 2197.6264 | G19: =VLOOKUP(A19,EV_Pivot!$A$4:$E$21,4,0) -> 10 | H19: =VLOOKUP(A19,ICE_Pivot!$A$4:$E$23,4,0) -> 3.8134328
A20: Subcompact Cars | B20: =VLOOKUP(A20,EV_Pivot!$A$4:$E$21,2,0) -> 62.5 | C20: =VLOOKUP(A20,ICE_Pivot!$A$4:$E$23,2,0) -> 23.40678 | D20: =VLOOKUP(A20,EV_Pivot!$A$4:$E$21,3,0) -> 940 | E20: =VLOOKUP(A20,ICE_Pivot!$A$4:$E$23,3,0) -> 2777.1186 | F20: =(E20-D20) -> 1837.1186 | G20: =VLOOKUP(A20,EV_Pivot!$A$4:$E$21,4,0) -> 10 | H20: =VLOOKUP(A20,ICE_Pivot!$A$4:$E$23,4,0) -> 4.7627119
A21: Two Seaters | B21: =VLOOKUP(A21,EV_Pivot!$A$4:$E$21,2,0) -> 58.25 | C21: =VLOOKUP(A21,ICE_Pivot!$A$4:$E$23,2,0) -> 19.627907 | D21: =VLOOKUP(A21,EV_Pivot!$A$4:$E$21,3,0) -> 1550 | E21: =VLOOKUP(A21,ICE_Pivot!$A$4:$E$23,3,0) -> 3418.6047 | F21: =(E21-D21) -> 1868.6047 | G21: =VLOOKUP(A21,EV_Pivot!$A$4:$E$21,4,0) -> 10 | H21: =VLOOKUP(A21,ICE_Pivot!$A$4:$E$23,4,0) -> 3.8604651

Sheet Cost_Model
A1: EV vs ICE — 5 Year Fuel Cost Comparison
A3: INPUTS
B4: EV | C4: ICE | D4: Source
A5: Avg Annual Fuel Cost ($) | B5: =EV_Pivot!C22 -> 942.40602 | C5: =ICE_Pivot!C24 -> 2641.6475 | D5: EPA 2025 dataset average
A6: Years of Ownership | B6: 5 | C6: 5 | D6: User input; adjust as needed
A8: CALCULATIONS
B9: EV | C9: ICE
A10: Total Fuel Cost ($) | B10: =B5*B6 -> 4712.0301 | C10: =C5*C6 -> 13208.237
A11: Total Fuel Savings choosing EV ($) | B11: =C10-B10 -> 8496.2073
A12: Avg EPA 5yr Savings | B12: =EV_Pivot!F22 -> 4853.7594 | D12: EPA Savings_5yr column average
A13: Avg 5yr Extra Spending | C13: =ICE_Pivot!E24 -> 4873.5994 | D13: Extra Spending 5yr Average
A15: Note: Purchase price, maintenance, insurance and depreciation are outside the scope of this EPA dataset.
